<!--
 * COPYRIGHT (C) 2010
 * RE2, INC.
 *
 * Author: RE2
 *
 * This file is a part of RobotModel, which was developed for the
 * DARPA ARM ROBOT Track C project.
 *
 * RobotModel is free software:
 * you can redistribute it and/or modify it under the terms of the GNU General
 * Public License as published by the Free Software Foundation, either version
 * 3 of the License, or (at your option) any later version.
 *
 * You should have received a copy of the GNU General Public License along
 * with this package.  If not, see <http://www.gnu.org/licenses/>.
 *
 * RE2, INC. disclaims all warranties with regard to this software, including
 * all implied warranties of merchantability and fitness, in no event shall
 * RE2, INC. be liable for any special, indirect or consequential damages or
 * any damages whatsoever resulting from loss of use, data or profits, whether
 * in an action of contract, negligence or other tortious action, arising out
 * of or in connection with the use or performance of this software.
-->

<robot xmlns:sensor="http://playerstage.sourceforge.net/gazebo/xmlschema/#sensor"
       xmlns:controller="http://playerstage.sourceforge.net/gazebo/xmlschema/#controller"
       xmlns:geom="http://playerstage.sourceforge.net/gazebo/xmlschema/#geom"
       xmlns:interface="http://playerstage.sourceforge.net/gazebo/xmlschema/#interface"
       xmlns:xacro="http://www.ros.org/wiki/xacro">

  <xacro:include filename="$(find barrett_hand_defs)/defs/materials.xml"/>

  <xacro:arg name="collision_model_full" default="true"/>
  <xacro:arg name="collision_model_simplified" default="false"/>
  <xacro:arg name="collision_model_enlargement" default="0.0"/>
  <xacro:arg name="collision_model_no_hands" default="false"/>

  <xacro:property name="homeDirectory" value="package://barrett_hand_defs" />
  <xacro:property name="highResModelDirectory" value="${homeDirectory}/meshes/splitModels" />
  <xacro:property name="PI" value="3.1415926535897931" />

  <property name="collision_model_enlargement" value="$(arg collision_model_enlargement)" />

  <xacro:macro name="palm" params="prefix parent *origin">

    <link name="${prefix}_HandPalmLink" >
      <inertial>
        <origin xyz="0.00035500 -0.00499005 0.04864979" />
        <mass value="0.63352875" />
        <inertia  ixx="0.00102103" ixy="0.00000775"  ixz="-0.00001230"
                                   iyy="0.00080944"  iyz="-0.00014417"
                                                     izz="0.00068788" />
      </inertial>

      <visual>
        <origin xyz="0 0 0" rpy="${PI} 0 0" />
        <geometry>
          <mesh filename="${homeDirectory}/meshes/HandPalmLink.dae"/>
        </geometry>
        <material name="bh_HandGrey"/>
      </visual>

      <xacro:unless value="$(arg collision_model_no_hands)">
      <!-- collision mesh used for whole arm motion planning -->
      <xacro:if value="$(arg collision_model_simplified)">
        <collision>
          <origin xyz="0 0 0.045" rpy="0 0 0" />
          <geometry>
            <cylinder radius="${0.045+collision_model_enlargement}" length="0.09"/>
          </geometry>
        </collision>
        <collision>
          <origin xyz="0 -0.035 0.07" rpy="0 0 0" />
          <geometry>
            <box size="${0.025+collision_model_enlargement*2} ${0.08+collision_model_enlargement*2} ${0.05+collision_model_enlargement*2}"/>
          </geometry>
        </collision>
      </xacro:if>

      <!-- collision mesh used for grasp planning -->
      <xacro:if value="$(arg collision_model_full)">
        <collision>
          <origin xyz="0 0 0" rpy="0 0 0" />
          <geometry>
            <mesh filename="${homeDirectory}/meshes/palm.stl"/>
          </geometry>
        </collision>
      </xacro:if>
      </xacro:unless>

      <!-- collision mesh used for RT self-collision avoidance -->
<!--
      <self_collision_checking>
        <origin xyz="0 0 0" rpy="0 0 0"/>
        <geometry>
          <convex>
            <point xyz="0.03 0.03 0.0" frame="${prefix}_HandPalmLink"/>
            <point xyz="-0.03 0.03 0.0" frame="${prefix}_HandPalmLink"/>
            <point xyz="-0.03 -0.03 0.0" frame="${prefix}_HandPalmLink"/>
            <point xyz="0.03 -0.03 0.0" frame="${prefix}_HandPalmLink"/>

            <point xyz="0.06 0 0" frame="${prefix}_HandFingerOneKnuckleOneLink"/>
            <point xyz="0.06 0 0" frame="${prefix}_HandFingerTwoKnuckleOneLink"/>
            <point xyz="0 -0.06 0.06" frame="${prefix}_HandPalmLink"/>

            <point xyz="0 0 0" frame="${prefix}_HandFingerOneKnuckleThreeLink"/>
            <point xyz="0 0 0" frame="${prefix}_HandFingerTwoKnuckleThreeLink"/>
            <point xyz="0 0 0" frame="${prefix}_HandFingerThreeKnuckleThreeLink"/>

            <point xyz="0.06 0 0" frame="${prefix}_HandFingerOneKnuckleThreeLink"/>
            <point xyz="0.06 0 0" frame="${prefix}_HandFingerTwoKnuckleThreeLink"/>
            <point xyz="0.06 0 0" frame="${prefix}_HandFingerThreeKnuckleThreeLink"/>
          </convex>
        </geometry>
      </self_collision_checking>
-->

      <self_collision_checking>
        <origin xyz="0.0 0.0 0.02" rpy="0 0 0"/>
        <geometry>
          <sphere radius="0.06"/>
        </geometry>
      </self_collision_checking>

    </link>

    <gazebo reference="${prefix}_HandPalmLink">
      <turnGravityOff>false</turnGravityOff>
    </gazebo>

    <joint name="${prefix}_HandPalmJoint" type="fixed">
      <parent link="${parent}"/>
      <child link="${prefix}_HandPalmLink"/>
      <insert_block name="origin"/>
      <provideFeedback value="true"/> 
    </joint>

    <link name="${prefix}_HandGripLink" >
    </link>

    <gazebo reference="${prefix}_HandGripLink">
      <turnGravityOff>false</turnGravityOff>
    </gazebo>

    <joint name="${prefix}_HandGripJoint" type="fixed">
      <parent link="${prefix}_HandPalmLink"/>
      <child link="${prefix}_HandGripLink"/>
      <origin rpy="0 0 0" xyz="0 0 0.12"/>
    </joint>

  </xacro:macro>

  <xacro:macro name="KnuckleOne" params="prefix number xyz rpy axis">

    <link name="${prefix}_HandFinger${number}KnuckleOneLink">
      <visual>
        <origin xyz="0 0 -0.017" rpy="${0.5 * PI} 0 -${0.5 * PI}" />
        <geometry>
          <mesh filename="${homeDirectory}/meshes/KnuckleOneLink.dae"/>
        </geometry>
        <material name="bh_HandGrey"/>
      </visual>
      <inertial>
        <origin xyz="0.03201666 -0.00086502 0.00890075" />
        <mass value="0.16252678" />
        <inertia  ixx="0.00002567" ixy="-0.00000146"  ixz="0.00001128"
                  iyy="0.00008818"   iyz="-0.00000094"
                  izz="0.00007827" />
      </inertial>

      <xacro:unless value="$(arg collision_model_no_hands)">
      <!-- collision mesh used for whole arm motion planning -->
      <xacro:if value="$(arg collision_model_simplified)">
        <collision>
          <origin xyz="0.03 0 0.005" rpy="0 0 0" />
          <geometry>
            <box size="${0.08+collision_model_enlargement*2} ${0.025+collision_model_enlargement*2} ${0.05+collision_model_enlargement*2}"/>
          </geometry>
        </collision>
      </xacro:if>

      <!-- collision mesh used for grasp planning -->
      <xacro:if value="$(arg collision_model_full)">
        <collision>
          <origin xyz="0 0 -0.0045" rpy="${0.5 * PI} 0 -${0.5 * PI}" />
          <geometry>
            <mesh filename="${homeDirectory}/meshes/firstFingerLink.stl"/>
          </geometry>
        </collision>
      </xacro:if>
      </xacro:unless>

    </link>

    <gazebo reference="${prefix}_HandFinger${number}KnuckleOneLink">
      <turnGravityOff>false</turnGravityOff>
    </gazebo>

    <joint name="${prefix}_HandFinger${number}KnuckleOneJoint" type="revolute">
      <parent link="${prefix}_HandPalmLink"/>
      <child link="${prefix}_HandFinger${number}KnuckleOneLink"/>
      <origin xyz="${xyz}" rpy="${rpy}"/>
      <axis xyz="${axis}"/>
      <limit effort="1" lower="0" upper="${PI}" velocity="3.27"/>
      <dynamics damping="0.1"/>
    </joint>
    <gazebo reference="${prefix}_HandFinger${number}KnuckleOneJoint">
      <provideFeedback>true</provideFeedback>
    </gazebo>
  </xacro:macro>


  <xacro:macro name="KnuckleTwo" params="parent prefix number xyz rpy">

    <link name="${prefix}_HandFinger${number}KnuckleTwoLink">
      <visual>
        <origin xyz="0 0 0" rpy="${PI} ${0.5 * PI} 0" />
        <geometry>
          <mesh filename="${homeDirectory}/meshes/KnuckleTwoLink.dae"/>
        </geometry>
        <material name="bh_HandGrey"/>
      </visual>
      <inertial>
        <origin xyz=".031720 .001070 -.000586" />
        <mass value="0.057957" />
        <inertia  ixx="0.00000461" ixy="0.00000003"  ixz="0.00000164"
                                   iyy="0.00003590"  iyz="0.00000004"
                                                     izz="0.00003682" />
      </inertial>

      <xacro:unless value="$(arg collision_model_no_hands)">
      <!-- collision mesh used for whole arm motion planning -->
      <xacro:if value="$(arg collision_model_simplified)">
        <collision>
          <origin xyz="0.03 0 0" rpy="0 0 0" />
          <geometry>
            <box size="${0.07+collision_model_enlargement*2} ${0.03+collision_model_enlargement*2} ${0.022+collision_model_enlargement*2}"/>
          </geometry>
        </collision>
      </xacro:if>
      <!-- collision mesh used for grasp planning -->
      <xacro:if value="$(arg collision_model_full)">
        <collision>
          <origin xyz="0 0 0" rpy="${PI} ${0.5 * PI} 0" />
          <geometry>
            <mesh filename="${homeDirectory}/meshes/secondFingerLink.stl"/>
          </geometry>
        </collision>
      </xacro:if>
      </xacro:unless>

      <self_collision_checking>
        <origin xyz="0.03 0.0 0.0" rpy="0 1.57075 0"/>
        <geometry>
          <capsule radius="0.01" length="0.06"/>
        </geometry>
      </self_collision_checking>
<!--
      <self_collision_checking>
        <origin xyz="0.04 -0.01 0.0" rpy="0 1.57075 -0.5"/>
        <geometry>
          <capsule radius="0.01" length="0.1"/>
        </geometry>
      </self_collision_checking>
-->
    </link>

    <gazebo reference="${prefix}_HandFinger${number}KnuckleTwoLink">
      <turnGravityOff>false</turnGravityOff>
    </gazebo>

    <joint name="${prefix}_HandFinger${number}KnuckleTwoJoint" type="revolute">
      <parent link="${parent}"/>
      <child link="${prefix}_HandFinger${number}KnuckleTwoLink"/>
      <origin xyz="${xyz}" rpy="${rpy}"/>
      <axis xyz="0 0 -1"/>
                      <!-- 122 degrees - start orientation of 0.4 degrees-->
      <limit effort="1" lower="0" upper="2.443388889" velocity="3.27"/>
      <dynamics damping="0.05"/>
    </joint>
    <gazebo reference="${prefix}_HandFinger${number}KnuckleTwoJoint">
      <provideFeedback>true</provideFeedback>
    </gazebo>
  </xacro:macro>

  <xacro:macro name="KnuckleThree" params="prefix number with_optoforce">

    <link name="${prefix}_HandFinger${number}KnuckleThreeLink">
      <visual>
        <origin xyz="0 0 0" rpy="0 ${0.5 * PI} 0" />
        <geometry>
          <xacro:if value="${with_optoforce}">
            <mesh filename="${homeDirectory}/meshes/KnuckleThreeOptoforceBaseLink.dae"/>
          </xacro:if>
          <xacro:unless value="${with_optoforce}">
            <mesh filename="${homeDirectory}/meshes/KnuckleThreeLink.dae"/>
          </xacro:unless>
        </geometry>
        <material name="bh_HandGrey"/>
      </visual>
<!--      <inertial>
        <origin xyz="0.01970974 0.00182016 0.00020041" />
        <mass value="0.03421781" />
        <inertia  ixx="0.00000287" ixy="0.00000091"  ixz="-0.00000007"
                                   iyy="0.00001329"  iyz="-0.00000002"
                                                     izz="0.00001214" />
      </inertial>
-->
      <inertial>
        <origin xyz="0.01970974 0.00182016 0.00020041" />
        <mass value="0.03421781" />
        <inertia  ixx="0.00000461" ixy="0.00000003"  ixz="0.00000164"
                                   iyy="0.00003590"  iyz="0.00000004"
                                                     izz="0.00003682" />
      </inertial>

      <xacro:unless value="$(arg collision_model_no_hands)">
      <!-- collision mesh used for whole arm motion planning -->
      <xacro:if value="$(arg collision_model_simplified)">
        <collision>
          <origin xyz="0.025 0 0" rpy="0 0 0" />
          <geometry>
            <box size="${0.07+collision_model_enlargement*2} ${0.02+collision_model_enlargement*2} ${0.022+collision_model_enlargement*2}"/>
          </geometry>
        </collision>
      </xacro:if>
      <!-- collision mesh used for grasp planning -->
      <xacro:if value="$(arg collision_model_full)">
        <collision>
          <origin xyz="0 0 0" rpy="0 0 0" />
          <geometry>
            <xacro:if value="${with_optoforce}">
              <mesh filename="${homeDirectory}/meshes/thirdFingerOptoforceBaseLink.stl"/>
            </xacro:if>
            <xacro:unless value="${with_optoforce}">
              <mesh filename="${homeDirectory}/meshes/thirdFingerLink.stl"/>
            </xacro:unless>
          </geometry>
        </collision>
      </xacro:if>
      </xacro:unless>

      <self_collision_checking>
        <origin xyz="0.025 0.0 0.0" rpy="0 1.57075 0"/>
        <geometry>
          <capsule radius="0.0075" length="0.05"/>
        </geometry>
      </self_collision_checking>

    </link>

    <gazebo reference="${prefix}_HandFinger${number}KnuckleThreeLink">
      <turnGravityOff>false</turnGravityOff>
    </gazebo>
    <joint name="${prefix}_HandFinger${number}KnuckleThreeJoint" type="revolute">
      <parent link="${prefix}_HandFinger${number}KnuckleTwoLink"/>
      <child link="${prefix}_HandFinger${number}KnuckleThreeLink"/>
                                  <!-- 39.56 degrees -->
      <origin xyz="0.07 0 0" rpy="0 0 -0.690452252"/>
      <axis xyz="0 0 -1"/>
                          <!-- measured max angle is 94.  so upper limit is 94 - start orientation (42 degrees)-->
      <limit effort="1" lower="0" upper="0.837733333" velocity="3.27"/>
      <dynamics damping="0.05"/>
    </joint>
    <gazebo reference="${prefix}_HandFinger${number}KnuckleThreeJoint">
      <provideFeedback>true</provideFeedback>
    </gazebo>

    <xacro:if value="${with_optoforce}">
        <link name="${prefix}_HandFinger${number}KnuckleThreeOptoforceBase" >
          <visual>
            <origin xyz="0 0 0" rpy="0 0 0" />
            <geometry>
              <sphere radius="0.01"/>
            </geometry>
            <material name="bh_Black"/>
          </visual>
        </link>
        <joint name="${prefix}_HandFinger${number}KnuckleThreeOptoforceBaseJoint" type="fixed">
          <parent link="${prefix}_HandFinger${number}KnuckleThreeLink"/>
          <child link="${prefix}_HandFinger${number}KnuckleThreeOptoforceBase"/>
          <origin rpy="0 ${PI/2} -${35.0 * PI / 180.0}" xyz="0.04486 -0.00685 0"/>
        </joint>

        <gazebo reference="${prefix}_HandFinger${number}KnuckleThreeOptoforceBase">
          <turnGravityOff>false</turnGravityOff>
        </gazebo>

        <link name="${prefix}_HandFinger${number}KnuckleThreeOptoforceSensor" >
          <inertial>
            <origin xyz="0 0 0" />
            <mass value="0.003421781" />
            <inertia  ixx="0.000000287" ixy="0.000000091"  ixz="-0.000000007"
                                         iyy="0.000001329"  iyz="-0.000000002"
                                                             izz="0.000001214" />
          </inertial>
          <collision>
            <origin xyz="0 0 0" rpy="0 0 0" />
            <geometry>
              <sphere radius="0.01"/>
            </geometry>
          </collision>
        </link>
        <joint name="${prefix}_HandFinger${number}KnuckleThreeOptoforceJoint" type="prismatic">
          <parent link="${prefix}_HandFinger${number}KnuckleThreeLink"/>
          <child link="${prefix}_HandFinger${number}KnuckleThreeOptoforceSensor"/>
          <origin rpy="0 ${PI/2} -${35.0 * PI / 180.0}" xyz="0.04486 -0.00685 0"/>

          <axis xyz="0 0 1"/>
          <limit effort="2" lower="-0.005" upper="0.005" velocity="0.1"/>
          <dynamics damping="0.1"/>
        </joint>

        <gazebo reference="${prefix}_HandFinger${number}KnuckleThreeOptoforceJoint">
          <provideFeedback>true</provideFeedback>
        </gazebo>

        <gazebo reference="${prefix}_HandFinger${number}KnuckleThreeOptoforceSensor">
          <turnGravityOff>false</turnGravityOff>
        </gazebo>
<!--
        <link name="${prefix}_HandFinger${number}KnuckleThreeOptoforceBase" >
        </link>
        <joint name="${prefix}_HandFinger${number}KnuckleThreeOptoforceBaseJoint" type="fixed">
          <parent link="${prefix}_HandFinger${number}KnuckleThreeLink"/>
          <child link="${prefix}_HandFinger${number}KnuckleThreeOptoforceBase"/>
          <origin rpy="0 0 -${35.0 * PI / 180.0}" xyz="0.0415 -0.0045 0"/>
        </joint>

        <link name="${prefix}_HandFinger${number}KnuckleThreeOptoforce" >
        </link>
        <joint name="${prefix}_HandFinger${number}KnuckleThreeOptoforceJoint" type="fixed">
          <parent link="${prefix}_HandFinger${number}KnuckleThreeOptoforceBase"/>
          <child link="${prefix}_HandFinger${number}KnuckleThreeOptoforce"/>
          <origin rpy="0 ${PI/2} 0" xyz="0.005 0 0"/>
        </joint>
-->
    </xacro:if>
  </xacro:macro>

  <xacro:macro name="fingers" params="parent prefix number xyz rpy with_optoforce">
    <xacro:KnuckleTwo parent="${parent}" prefix="${prefix}" number="${number}" xyz="${xyz}" rpy="${rpy}" />
    <xacro:KnuckleThree prefix="${prefix}" number="${number}" with_optoforce="${with_optoforce}"/>
  </xacro:macro>

    <xacro:macro name="barret_hand" params="prefix parent *origin with_optoforce">

        <xacro:palm prefix="${prefix}" parent="${parent}">
            <insert_block name="origin"/>
        </xacro:palm>
    
        <xacro:fingers prefix="${prefix}" parent="${prefix}_HandPalmLink" number="Three" xyz="0 -0.05 0.0754" rpy="-${0.5 * PI} 0 -${0.5 * PI}" with_optoforce="${with_optoforce}"/>

        <xacro:KnuckleOne prefix="${prefix}" number="One" xyz=".02497 0 0.0587966" rpy="0 0 ${0.5 * PI}" axis="0 0 -1"/>
        <xacro:fingers prefix="${prefix}" parent="${prefix}_HandFingerOneKnuckleOneLink" number="One" xyz=".05 0 0.0166034" rpy="-${0.5 * PI} 0 0" with_optoforce="${with_optoforce}"/>

        <xacro:KnuckleOne prefix="${prefix}" number="Two" xyz="-.02497 0 0.0587966" rpy="0 0 ${0.5 * PI}" axis ="0 0 1"/>
        <xacro:fingers prefix="${prefix}" parent="${prefix}_HandFingerTwoKnuckleOneLink" number="Two" xyz=".05 0 0.0166034" rpy="-${0.5 * PI} 0 0" with_optoforce="${with_optoforce}"/>
<!--        <xacro:fingers prefix="${prefix}" parent="${prefix}_HandFingerTwoKnuckleOneLink" number="Two" xyz=".05 0 0.0166034" rpy="-${0.5 * PI} -0.0429350996 0"/>-->

</xacro:macro>


</robot>
